Workbook

Sheet Original_Data
A1: name | B1: Categories | C1: engagament | D1: color | E1: Expertise Areas | F1: Engagement Summary
A2: AWC | B2: Air Univerity | C2: 5 | D2: red | E2: AI & Data; Education & PME; Futures & Strategy | F2: Used Project SE-OA to review AWC curriculum for joint-warfighting and lethality alignment. Also supported Alpha Blue and AI-enabled reading, writing, and research.
A3: ACSC | B3: Air Univerity | C3: 60 | D3: red | E3: AI & Data; Education & PME; Wargaming; Fabrication & sUAS; Innovation & Design | F3: Partnered on AI study skills, Project CHUCK, Project DRADIS, Praxeum, wargame maps, Alpha Blue research, and sUAS prototypes including Centurion, Killer Robots, and Maple Seed.
A4: SOS | B4: Air Univerity | C4: 19 | D4: red | E4: Education & PME; Wargaming; Innovation & Design | F4: Supported AFWI/Project CHUCK, Praxeum, AUAR research, Echo Lab wargame materials, AI 101, and LEGO Serious Play instruction.
A5: Lemay | B5: Air Univerity | C5: 3 | D5: red | E5: Wargaming; AI & Data; Education & PME | F5: Requested and supported Project CHUCK, joint-planning applications, Power BI training, wargame materials, and sUAS work.
A6: AFIT | B6: Air Univerity | C6: 25 | D6: red | E6: Education & PME; Innovation & Design; AI & Data | F6: Supported Education With Industry fellows and coaches through solution framing, double-diamond design, LEGO Serious Play, and AI-enabled problem solving.
A7: Barnes | B7: Air Univerity | C7: 4 | D7: red | E7: Education & PME; AI & Data; Wargaming | F7: Received AI literacy and curriculum-development training and collaborated on Project CHUCK, Kingfish ACE, learning objectives, KPIs, and SBIR exploration.
A8: AFGC | B8: Air Univerity | C8: 2 | D8: red | E8: Education & PME; AI & Data; Policy & Acquisition
A9: Blue Horizons | B9: Air Univerity | C9: 1 | D9: red | E9: AI & Data; Wargaming; Futures & Strategy; Innovation & Design ; Fabrication & sUAS; Human Performance
A10: AU HQ | B10: Air Univerity | C10: 5 | D10: red | E10: AI & Data; Education & PME; Policy & Acquisition | F10: Participated in AI 101, Power BI, VECTOR/Beacon faculty development, Praxeum, and cross-AU AI policy roundtables.
A11: Eaker Center | B11: Air Univerity | C11: 2 | D11: red | E11: Education & PME; Innovation & Design; AI & Data | F11: Partnered on Power BI instruction and Wing Chaplain Course support using LEGO Serious Play and problem-framing methods.
A12: MSFRIC | B12: Air Univerity | C12: 2 | D12: red | E12: AI & Data; Software & Automation; Education & PME | F12: Partnered on CODEX DROID, a custom GPT for the AU Style Guide, article taxonomy, indexing, and publishing workflows.
A13: IOS | B13: Air Univerity | C13: 2 | D13: red | E13: Education & PME; Wargaming; Innovation & Design | F13: Integrated the Eagle Institute into AY26 onboarding to expose international officers to innovation, AI, and wargaming.
A14: SAASS | B14: Air Univerity | C14: 2 | D14: red | E14: Education & PME; Wargaming; Futures & Strategy
A15: Auburn | B15: Academia | C15: 10 | D15: Blue | E15: AI & Data; Human Performance; Community & Workforce; Education & PME | F15: Collaborated through the Biggio Center, Warrior Research Center, GearUP/PELLA, course redesign, and Invention Convention Alabama.
A16: MPS | B16: Academia | C16: 1 | D16: Blue | E16: Community & Workforce; Education & PME | F16: Partnered on a Goodwyn Middle School STEM Café session featuring robotics, drones, AR/VR, and 3D printing.
A17: MIT | B17: Academia | C17: 3 | D17: Blue | E17: AI & Data; Education & PME; Innovation & Design; Innovation & Design | F17: Supported the Air Power U Summer Workshop Series on AI for research, curriculum, and learning-space design.
A18: Troy | B18: Academia | C18: 7 | D18: Blue | E18: AI & Data; Software & Automation; Fabrication & sUAS; Innovation & Design | F18: Provided faculty and intern support for AI workshops, ACSC hackathons, Project ATLAS, and acoustic drone-detection research.
A19: ASU | B19: Academia | C19: 2 | D19: Blue | E19: Fabrication & sUAS; Education & PME
A20: Stanford | B20: Academia | C20: 5 | D20: Blue | E20: AI & Data; Education & PME; Policy & Acquisition | F20: Partnered on Phoenix Dialogue through the Deliberative Democracy Lab and supported internships focused on AI in PME.
A21: AUM | B21: Academia | C21: 6 | D21: Blue | E21: Software & Automation; Fabrication & sUAS; Innovation & Design; Community & Workforce | F21: Collaborated on ACSC hackathons, Project Killer Robots, internships, and prototyping support.
A22: William & Mary | B22: Academia | C22: 2 | D22: Blue | E22: AI & Data; Wargaming; Education & PME | F22: An intern supported further Project CHUCK testing at USAFA for Operation Northern Eclipse.
A23: Treholm | B23: Academia | C23: 4 | D23: Blue | E23: Community & Workforce; Education & PME | F23: Identified as an internship partner. No specific project outcome was provided.
A24: Invoke Public Sector | B24: Industry | C24: 2 | D24: Yellow | E24: Software & Automation; AI & Data | F24: Partnered on robotic process automation, workflow automation, and commercial AI training.
A25: MGM Tech Lab | B25: Industry | C25: 5 | D25: Yellow | E25: Policy & Acquisition; Innovation & Design; Community & Workforce | F25: Supported Defense Accelerator Demo Day, connecting businesses with defense SMEs on critical technologies and acquisition processes.
A26: Aptima | B26: Industry | C26: 2 | D26: Yellow | E26: Education & PME; AI & Data; Software & Automation
A27: Google Public Sector | B27: Industry | C27: 2 | D27: Yellow | E27: Education & PME; AI & Data; Innovation & Design; Software & Automation
A28: Decision Advantage AI | B28: Industry | C28: 2 | D28: Yellow | E28: Wargaming; AI & Data
A29: QuantHub | B29: Industry | C29: 2 | D29: Yellow | E29: AI & Data; Education & PME
A30: Digital University | B30: Industry | C30: 2 | D30: Yellow | E30: Education & PME; AI & Data; Software & Automation
A31: Deloitte | B31: Industry | C31: 2 | D31: Yellow | E31: AI & Data; Policy & Acquisition | F31: Connected during the Alabama Higher Education AI Exchange to discuss AI integration, academic integrity, and cross-sector adoption.
A32: HII | B32: Industry | C32: 11 | D32: Yellow | E32: Innovation & Design; Community & Workforce; Policy & Acquisition
A33: AWS | B33: Industry | C33: 8 | D33: Yellow | E33: AI & Data; Wargaming; Software & Automation | F33: Expressed interest in supporting a prototype AI-driven wargame.
A34: OMNI Federal | B34: Industry | C34: 6 | D34: Yellow | E34: Futures & Strategy; Education & PME; Software & Automation | F34: Built and demonstrated a Futures Literacy virtual mini-course prototype under a CRADA; Johns Hopkins agreed to design the curriculum.
A35: Coca Cola | B35: Industry | C35: 6 | D35: Yellow | E35: Education & PME | F35: Listed as a partner for curriculum and specialized-topic programming.
A36: SBIR Advisor | B36: Industry | C36: 6 | D36: Yellow | E36: Innovation & Design; Education & PME; AI & Data; Fabrication & sUAS
A37: MGM Chamber of Commerce | B37: Industry | C37: 1 | D37: Yellow | E37: Community & Workforce.
A38: AFRL/RW | B38: MIL & GOV | C38: 1 | D38: Green | E38: AI & Data; Fabrication & sUAS
A39: Pathfinder/SSG | B39: MIL & GOV | C39: 9 | D39: Green | E39: Innovation & Design; Futures & Strategy
A40: BESPIN | B40: MIL & GOV | C40: 8 | D40: Green | E40: Software & Automation; Education & PME; Software & Automation; Innovation & Design | F40: Listed as a partner for curriculum and specialized-topic programming.
...

Sheet Stakeholders
A1: Organization | B1: Organization Type | C1: Engagement Score | D1: Color | E1: Expertise Areas | F1: Engagement Summary
A2: AWC | B2: Air University | C2: 5 | D2: Red | E2: AI & Data; Education & PME; Futures & Strategy | F2: Used Project SE-OA to review AWC curriculum for joint-warfighting and lethality alignment. Also supported Alpha Blue and AI-enabled reading, writing, and research.
A3: ACSC | B3: Air University | C3: 60 | D3: Red | E3: AI & Data; Education & PME; Wargaming; Fabrication & sUAS; Innovation & Design | F3: Partnered on AI study skills, Project CHUCK, Project DRADIS, Praxeum, wargame maps, Alpha Blue research, and sUAS prototypes including Centurion, Killer Robots, and Maple Seed.
A4: SOS | B4: Air University | C4: 19 | D4: Red | E4: Education & PME; Wargaming; Innovation & Design | F4: Supported AFWI/Project CHUCK, Praxeum, AUAR research, Echo Lab wargame materials, AI 101, and LEGO Serious Play instruction.
A5: Lemay | B5: Air University | C5: 3 | D5: Red | E5: Wargaming; AI & Data; Education & PME | F5: Requested and supported Project CHUCK, joint-planning applications, Power BI training, wargame materials, and sUAS work.
A6: AFIT | B6: Air University | C6: 25 | D6: Red | E6: Education & PME; Innovation & Design; AI & Data | F6: Supported Education With Industry fellows and coaches through solution framing, double-diamond design, LEGO Serious Play, and AI-enabled problem solving.
A7: Barnes | B7: Air University | C7: 4 | D7: Red | E7: Education & PME; AI & Data; Wargaming | F7: Received AI literacy and curriculum-development training and collaborated on Project CHUCK, Kingfish ACE, learning objectives, KPIs, and SBIR exploration.
A8: AFGC | B8: Air University | C8: 2 | D8: Red | E8: Education & PME; AI & Data; Policy & Acquisition
A9: Blue Horizons | B9: Air University | C9: 1 | D9: Red | E9: AI & Data; Wargaming; Futures & Strategy; Innovation & Design; Fabrication & sUAS; Human Performance
A10: AU HQ | B10: Air University | C10: 5 | D10: Red | E10: AI & Data; Education & PME; Policy & Acquisition | F10: Participated in AI 101, Power BI, VECTOR/Beacon faculty development, Praxeum, and cross-AU AI policy roundtables.
A11: Eaker Center | B11: Air University | C11: 2 | D11: Red | E11: Education & PME; Innovation & Design; AI & Data | F11: Partnered on Power BI instruction and Wing Chaplain Course support using LEGO Serious Play and problem-framing methods.
A12: MSFRIC | B12: Air University | C12: 2 | D12: Red | E12: AI & Data; Software & Automation; Education & PME | F12: Partnered on CODEX DROID, a custom GPT for the AU Style Guide, article taxonomy, indexing, and publishing workflows.
A13: IOS | B13: Air University | C13: 2 | D13: Red | E13: Education & PME; Wargaming; Innovation & Design | F13: Integrated the Eagle Institute into AY26 onboarding to expose international officers to innovation, AI, and wargaming.
A14: SAASS | B14: Air University | C14: 2 | D14: Red | E14: Education & PME; Wargaming; Futures & Strategy
A15: Auburn | B15: Academia | C15: 10 | D15: Blue | E15: AI & Data; Human Performance; Community & Workforce; Education & PME | F15: Collaborated through the Biggio Center, Warrior Research Center, GearUP/PELLA, course redesign, and Invention Convention Alabama.
A16: MPS | B16: Academia | C16: 1 | D16: Blue | E16: Community & Workforce; Education & PME | F16: Partnered on a Goodwyn Middle School STEM Café session featuring robotics, drones, AR/VR, and 3D printing.
A17: MIT | B17: Academia | C17: 3 | D17: Blue | E17: AI & Data; Education & PME; Innovation & Design | F17: Supported the Air Power U Summer Workshop Series on AI for research, curriculum, and learning-space design.
A18: Troy | B18: Academia | C18: 7 | D18: Blue | E18: AI & Data; Software & Automation; Fabrication & sUAS; Innovation & Design | F18: Provided faculty and intern support for AI workshops, ACSC hackathons, Project ATLAS, and acoustic drone-detection research.
A19: ASU | B19: Academia | C19: 2 | D19: Blue | E19: Fabrication & sUAS; Education & PME
A20: Stanford | B20: Academia | C20: 5 | D20: Blue | E20: AI & Data; Education & PME; Policy & Acquisition | F20: Partnered on Phoenix Dialogue through the Deliberative Democracy Lab and supported internships focused on AI in PME.
A21: AUM | B21: Academia | C21: 6 | D21: Blue | E21: Software & Automation; Fabrication & sUAS; Innovation & Design; Community & Workforce | F21: Collaborated on ACSC hackathons, Project Killer Robots, internships, and prototyping support.
A22: William & Mary | B22: Academia | C22: 2 | D22: Blue | E22: AI & Data; Wargaming; Education & PME | F22: An intern supported further Project CHUCK testing at USAFA for Operation Northern Eclipse.
A23: Treholm | B23: Academia | C23: 4 | D23: Blue | E23: Community & Workforce; Education & PME | F23: Identified as an internship partner. No specific project outcome was provided.
A24: Invoke Public Sector | B24: Industry | C24: 2 | D24: Yellow | E24: Software & Automation; AI & Data | F24: Partnered on robotic process automation, workflow automation, and commercial AI training.
A25: MGM Tech Lab | B25: Industry | C25: 5 | D25: Yellow | E25: Policy & Acquisition; Innovation & Design; Community & Workforce | F25: Supported Defense Accelerator Demo Day, connecting businesses with defense SMEs on critical technologies and acquisition processes.
A26: Aptima | B26: Industry | C26: 2 | D26: Yellow | E26: Education & PME; AI & Data; Software & Automation
A27: Google Public Sector | B27: Industry | C27: 2 | D27: Yellow | E27: Education & PME; AI & Data; Innovation & Design; Software & Automation
A28: Decision Advantage AI | B28: Industry | C28: 2 | D28: Yellow | E28: Wargaming; AI & Data
A29: QuantHub | B29: Industry | C29: 2 | D29: Yellow | E29: AI & Data; Education & PME
A30: Digital University | B30: Industry | C30: 2 | D30: Yellow | E30: Education & PME; AI & Data; Software & Automation
A31: Deloitte | B31: Industry | C31: 2 | D31: Yellow | E31: AI & Data; Policy & Acquisition | F31: Connected during the Alabama Higher Education AI Exchange to discuss AI integration, academic integrity, and cross-sector adoption.
A32: HII | B32: Industry | C32: 11 | D32: Yellow | E32: Innovation & Design; Community & Workforce; Policy & Acquisition
A33: AWS | B33: Industry | C33: 8 | D33: Yellow | E33: AI & Data; Wargaming; Software & Automation | F33: Expressed interest in supporting a prototype AI-driven wargame.
A34: OMNI Federal | B34: Industry | C34: 6 | D34: Yellow | E34: Futures & Strategy; Education & PME; Software & Automation | F34: Built and demonstrated a Futures Literacy virtual mini-course prototype under a CRADA; Johns Hopkins agreed to design the curriculum.
A35: Coca Cola | B35: Industry | C35: 6 | D35: Yellow | E35: Education & PME | F35: Listed as a partner for curriculum and specialized-topic programming.
A36: SBIR Advisor | B36: Industry | C36: 6 | D36: Yellow | E36: Innovation & Design; Education & PME; AI & Data; Fabrication & sUAS
A37: MGM Chamber of Commerce | B37: Industry | C37: 1 | D37: Yellow | E37: Community & Workforce
A38: AFRL/RW | B38: Military & Government | C38: 1 | D38: Green | E38: AI & Data; Fabrication & sUAS
A39: Pathfinder/SSG | B39: Military & Government | C39: 9 | D39: Green | E39: Innovation & Design; Futures & Strategy
A40: BESPIN | B40: Military & Government | C40: 8 | D40: Green | E40: Software & Automation; Education & PME; Innovation & Design | F40: Listed as a partner for curriculum and specialized-topic programming.
...

Sheet Expertise_Links
A1: Expertise | B1: Organization | C1: Organization Type | D1: Engagement Score | E1: Color | F1: Engagement Summary
A2: AI & Data | B2: ACSC | C2: Air University | D2: 60 | E2: Red | F2: Partnered on AI study skills, Project CHUCK, Project DRADIS, Praxeum, wargame maps, Alpha Blue research, and sUAS prototypes including Centurion, Killer Robots, and Maple Seed.
A3: AI & Data | B3: AFIT | C3: Air University | D3: 25 | E3: Red | F3: Supported Education With Industry fellows and coaches through solution framing, double-diamond design, LEGO Serious Play, and AI-enabled problem solving.
A4: AI & Data | B4: Auburn | C4: Academia | D4: 10 | E4: Blue | F4: Collaborated through the Biggio Center, Warrior Research Center, GearUP/PELLA, course redesign, and Invention Convention Alabama.
A5: AI & Data | B5: AWS | C5: Industry | D5: 8 | E5: Yellow | F5: Expressed interest in supporting a prototype AI-driven wargame.
A6: AI & Data | B6: Troy | C6: Academia | D6: 7 | E6: Blue | F6: Provided faculty and intern support for AI workshops, ACSC hackathons, Project ATLAS, and acoustic drone-detection research.
A7: AI & Data | B7: SBIR Advisor | C7: Industry | D7: 6 | E7: Yellow
A8: AI & Data | B8: AU HQ | C8: Air University | D8: 5 | E8: Red | F8: Participated in AI 101, Power BI, VECTOR/Beacon faculty development, Praxeum, and cross-AU AI policy roundtables.
A9: AI & Data | B9: AWC | C9: Air University | D9: 5 | E9: Red | F9: Used Project SE-OA to review AWC curriculum for joint-warfighting and lethality alignment. Also supported Alpha Blue and AI-enabled reading, writing, and research.
A10: AI & Data | B10: Stanford | C10: Academia | D10: 5 | E10: Blue | F10: Partnered on Phoenix Dialogue through the Deliberative Democracy Lab and supported internships focused on AI in PME.
A11: AI & Data | B11: Barnes | C11: Air University | D11: 4 | E11: Red | F11: Received AI literacy and curriculum-development training and collaborated on Project CHUCK, Kingfish ACE, learning objectives, KPIs, and SBIR exploration.
A12: AI & Data | B12: Lemay | C12: Air University | D12: 3 | E12: Red | F12: Requested and supported Project CHUCK, joint-planning applications, Power BI training, wargame materials, and sUAS work.
A13: AI & Data | B13: MIT | C13: Academia | D13: 3 | E13: Blue | F13: Supported the Air Power U Summer Workshop Series on AI for research, curriculum, and learning-space design.
A14: AI & Data | B14: 187th Fighter Wing | C14: Military & Government | D14: 2 | E14: Green
A15: AI & Data | B15: AFGC | C15: Air University | D15: 2 | E15: Red
A16: AI & Data | B16: Aptima | C16: Industry | D16: 2 | E16: Yellow
A17: AI & Data | B17: Army War College | C17: Military & Government | D17: 2 | E17: Green | F17: Participated in cross-service collaboration on AI adoption in professional military education.
A18: AI & Data | B18: Decision Advantage AI | C18: Industry | D18: 2 | E18: Yellow
A19: AI & Data | B19: Deloitte | C19: Industry | D19: 2 | E19: Yellow | F19: Connected during the Alabama Higher Education AI Exchange to discuss AI integration, academic integrity, and cross-sector adoption.
A20: AI & Data | B20: Digital University | C20: Industry | D20: 2 | E20: Yellow
A21: AI & Data | B21: Eaker Center | C21: Air University | D21: 2 | E21: Red | F21: Partnered on Power BI instruction and Wing Chaplain Course support using LEGO Serious Play and problem-framing methods.
A22: AI & Data | B22: Google Public Sector | C22: Industry | D22: 2 | E22: Yellow
A23: AI & Data | B23: Invoke Public Sector | C23: Industry | D23: 2 | E23: Yellow | F23: Partnered on robotic process automation, workflow automation, and commercial AI training.
A24: AI & Data | B24: MSFRIC | C24: Air University | D24: 2 | E24: Red | F24: Partnered on CODEX DROID, a custom GPT for the AU Style Guide, article taxonomy, indexing, and publishing workflows.
A25: AI & Data | B25: QuantHub | C25: Industry | D25: 2 | E25: Yellow
A26: AI & Data | B26: William & Mary | C26: Academia | D26: 2 | E26: Blue | F26: An intern supported further Project CHUCK testing at USAFA for Operation Northern Eclipse.
A27: AI & Data | B27: AFRL/RW | C27: Military & Government | D27: 1 | E27: Green
A28: AI & Data | B28: Blue Horizons | C28: Air University | D28: 1 | E28: Red
A29: Community & Workforce | B29: HII | C29: Industry | D29: 11 | E29: Yellow
A30: Community & Workforce | B30: Auburn | C30: Academia | D30: 10 | E30: Blue | F30: Collaborated through the Biggio Center, Warrior Research Center, GearUP/PELLA, course redesign, and Invention Convention Alabama.
A31: Community & Workforce | B31: AUM | C31: Academia | D31: 6 | E31: Blue | F31: Collaborated on ACSC hackathons, Project Killer Robots, internships, and prototyping support.
A32: Community & Workforce | B32: MGM Tech Lab | C32: Industry | D32: 5 | E32: Yellow | F32: Supported Defense Accelerator Demo Day, connecting businesses with defense SMEs on critical technologies and acquisition processes.
A33: Community & Workforce | B33: Treholm | C33: Academia | D33: 4 | E33: Blue | F33: Identified as an internship partner. No specific project outcome was provided.
A34: Community & Workforce | B34: MGM Chamber of Commerce | C34: Industry | D34: 1 | E34: Yellow
A35: Community & Workforce | B35: MPS | C35: Academia | D35: 1 | E35: Blue | F35: Partnered on a Goodwyn Middle School STEM Café session featuring robotics, drones, AR/VR, and 3D printing.
A36: Education & PME | B36: ACSC | C36: Air University | D36: 60 | E36: Red | F36: Partnered on AI study skills, Project CHUCK, Project DRADIS, Praxeum, wargame maps, Alpha Blue research, and sUAS prototypes including Centurion, Killer Robots, and Maple Seed.
A37: Education & PME | B37: AFIT | C37: Air University | D37: 25 | E37: Red | F37: Supported Education With Industry fellows and coaches through solution framing, double-diamond design, LEGO Serious Play, and AI-enabled problem solving.
A38: Education & PME | B38: SOS | C38: Air University | D38: 19 | E38: Red | F38: Supported AFWI/Project CHUCK, Praxeum, AUAR research, Echo Lab wargame materials, AI 101, and LEGO Serious Play instruction.
A39: Education & PME | B39: Auburn | C39: Academia | D39: 10 | E39: Blue | F39: Collaborated through the Biggio Center, Warrior Research Center, GearUP/PELLA, course redesign, and Invention Convention Alabama.
A40: Education & PME | B40: BESPIN | C40: Military & Government | D40: 8 | E40: Green | F40: Listed as a partner for curriculum and specialized-topic programming.
...

Sheet Expertise
A1: Display Order | B1: Expertise | C1: Description | D1: Organization Count | E1: Total Engagement | F1: Average Engagement
A2: 1 | B2: AI & Data | C2: Artificial intelligence, data analytics, machine learning, and AI-enabled workflows. | D2: =COUNTIF(Expertise_Links!$A$2:$A$126,B2) | E2: =SUMIF(Expertise_Links!$A$2:$A$126,B2,Expertise_Links!$D$2:$D$126) | F2: =IF(D2=0,0,E2/D2)
A3: 2 | B3: Education & PME | C3: Curriculum, faculty development, learning design, and professional military education. | D3: =COUNTIF(Expertise_Links!$A$2:$A$126,B3) | E3: =SUMIF(Expertise_Links!$A$2:$A$126,B3,Expertise_Links!$D$2:$D$126) | F3: =IF(D3=0,0,E3/D3)
A4: 3 | B4: Wargaming | C4: Wargaming, scenario design, simulation, red teaming, and decision exercises. | D4: =COUNTIF(Expertise_Links!$A$2:$A$126,B4) | E4: =SUMIF(Expertise_Links!$A$2:$A$126,B4,Expertise_Links!$D$2:$D$126) | F4: =IF(D4=0,0,E4/D4)
A5: 4 | B5: Futures & Strategy | C5: Strategic foresight, futures literacy, scenario planning, and operational art. | D5: =COUNTIF(Expertise_Links!$A$2:$A$126,B5) | E5: =SUMIF(Expertise_Links!$A$2:$A$126,B5,Expertise_Links!$D$2:$D$126) | F5: =IF(D5=0,0,E5/D5)
A6: 5 | B6: Innovation & Design | C6: Human-centered design, rapid problem framing, prototyping, and innovation methods. | D6: =COUNTIF(Expertise_Links!$A$2:$A$126,B6) | E6: =SUMIF(Expertise_Links!$A$2:$A$126,B6,Expertise_Links!$D$2:$D$126) | F6: =IF(D6=0,0,E6/D6)
A7: 6 | B7: Software & Automation | C7: Software development, workflow automation, digital tools, and cloud-enabled solutions. | D7: =COUNTIF(Expertise_Links!$A$2:$A$126,B7) | E7: =SUMIF(Expertise_Links!$A$2:$A$126,B7,Expertise_Links!$D$2:$D$126) | F7: =IF(D7=0,0,E7/D7)
A8: 7 | B8: Fabrication & sUAS | C8: Rapid fabrication, prototyping, additive manufacturing, drones, and small UAS. | D8: =COUNTIF(Expertise_Links!$A$2:$A$126,B8) | E8: =SUMIF(Expertise_Links!$A$2:$A$126,B8,Expertise_Links!$D$2:$D$126) | F8: =IF(D8=0,0,E8/D8)
A9: 8 | B9: Human Performance | C9: Physical, cognitive, behavioral, and resilience-related performance. | D9: =COUNTIF(Expertise_Links!$A$2:$A$126,B9) | E9: =SUMIF(Expertise_Links!$A$2:$A$126,B9,Expertise_Links!$D$2:$D$126) | F9: =IF(D9=0,0,E9/D9)
A10: 9 | B10: Policy & Acquisition | C10: Policy, acquisition, transition pathways, contracting, and SBIR-related expertise. | D10: =COUNTIF(Expertise_Links!$A$2:$A$126,B10) | E10: =SUMIF(Expertise_Links!$A$2:$A$126,B10,Expertise_Links!$D$2:$D$126) | F10: =IF(D10=0,0,E10/D10)
A11: 10 | B11: Community & Workforce | C11: Community partnerships, workforce development, internships, and ecosystem engagement. | D11: =COUNTIF(Expertise_Links!$A$2:$A$126,B11) | E11: =SUMIF(Expertise_Links!$A$2:$A$126,B11,Expertise_Links!$D$2:$D$126) | F11: =IF(D11=0,0,E11/D11)

Sheet App_Config
A1: Setting | B1: Value | C1: Purpose
A2: Center Node | B2: AUiX | C2: Central node displayed when the network loads.
A3: Primary Navigation | B3: Expertise | C3: Expertise nodes appear as the first ring around AUiX.
A4: Secondary Nodes | B4: Organizations | C4: Organizations appear only after an expertise node is selected.
A5: Organization Filters | B5: Air University | Academia | Industry | Military & Government | C5: Use organization type as a filter, not as the first navigation layer.
A6: Node Size | B6: Engagement Score | C6: Use the existing engagement score to scale organization nodes.
A7: Organization Detail | B7: Engagement Summary | C7: Show the summary in a hover card or side panel when an organization is selected.
A8: Data Source | B8: Expertise_Links | C8: Recommended normalized table for the Streamlit network.

Sheet Data_Quality_Notes
A1: Issue | B1: Original | C1: Normalized / Action
A2: Column typo | B2: engagament | C2: Engagement Score
A3: Category typo | B3: Air Univerity | C3: Air University
A4: Category naming | B4: MIL & GOV | C4: Military & Government
A5: Whitespace | B5: Deloitte | C5: Deloitte
A6: Expertise punctuation | B6: Community & Workforce. | C6: Community & Workforce
A7: Expertise duplicate | B7: MIT: Innovation & Design twice | C7: Kept once
A8: Expertise duplicate | B8: BESPIN: Software & Automation twice | C8: Kept once
A9: Expertise spacing | B9: Futures & Strategy / Innovation & Design with leading or trailing spaces | C9: Trimmed spaces
A10: Blank helper rows | B10: Rows 45-56 contain no stakeholder names | C10: Excluded from normalized stakeholder/link tables; preserved in Original_Data
